<!--URDF generated by ONSHAPE BY PTC INC, 1.213-->
<robot name="simple_assembly">
    <link name="part_1">
        <inertial>
            <mass value="0.392289" />
            <origin xyz="-7.19431e-18 2.31112e-33 0.02825" rpy="0 -0 0" />
            <inertia ixx="0.000184016" ixy="0" ixz="0" iyy="0.000184016" iyz="0" izz="0.000159318" />
        </inertial>
        <visual>
            <origin xyz="-5.31105e-18 -1.74512e-18 0" rpy="0 -0 0" />
            <geometry>
                <mesh filename="package://simple_assembly/meshes/Part 1.stl" scale="1 1 1" />
            </geometry>
            <material name="0.800000_0.776471_0.713725_0.000000_0.000000">
                <texture />
                <color rgba="0.8 0.776471 0.713726 1" />
            </material>
        </visual>
    </link>
    <link name="part_1_1">
        <inertial>
            <mass value="0.347331" />
            <origin xyz="0.020796 1.20964e-08 -0.0428943" rpy="0 -0 0" />
            <inertia ixx="0.000768882" ixy="-1.68717e-10" ixz="0.000128098" iyy="0.00060734" iyz="8.33311e-11" izz="0.000443472" />
        </inertial>
        <visual>
            <origin xyz="1.47451e-17 5.86445e-18 -0.06225" rpy="0 -0 0" />
            <geometry>
                <mesh filename="package://simple_assembly/meshes/Part 1_1.stl" scale="1 1 1" />
            </geometry>
            <material name="0.094118_0.580392_0.545098_0.000000_0.000000">
                <texture />
                <color rgba="0.0941176 0.580392 0.545098 1" />
            </material>
        </visual>
    </link>
    <link name="part_1_10">
        <inertial>
            <mass value="0.347331" />
            <origin xyz="0.020796 1.20964e-08 -0.0428943" rpy="0 -0 0" />
            <inertia ixx="0.000768882" ixy="-1.68717e-10" ixz="0.000128098" iyy="0.00060734" iyz="8.33311e-11" izz="0.000443472" />
        </inertial>
        <visual>
            <origin xyz="1.47451e-17 5.86445e-18 -0.06225" rpy="0 -0 0" />
            <geometry>
                <mesh filename="package://simple_assembly/meshes/Part 1_1.stl" scale="1 1 1" />
            </geometry>
            <material name="0.094118_0.580392_0.545098_0.000000_0.000000">
                <texture />
                <color rgba="0.0941176 0.580392 0.545098 1" />
            </material>
        </visual>
    </link>
    <link name="part_1_11">
        <inertial>
            <mass value="0.284011" />
            <origin xyz="-0.0234111 -2.25131e-10 0.0361492" rpy="0 -0 0" />
            <inertia ixx="0.000368023" ixy="4.4845e-12" ixz="8.61899e-05" iyy="0.000382149" iyz="-7.95148e-12" izz="0.000153368" />
        </inertial>
        <visual>
            <origin xyz="0 0 -0.0002" rpy="0 -0 0" />
            <geometry>
                <mesh filename="package://simple_assembly/meshes/Part 1_3.stl" scale="1 1 1" />
            </geometry>
            <material name="0.615686_0.811765_0.929412_0.000000_0.000000">
                <texture />
                <color rgba="0.615686 0.811765 0.929412 1" />
            </material>
        </visual>
    </link>
    <link name="part_1_12">
        <inertial>
            <mass value="0.392289" />
            <origin xyz="-1.88325e-18 2.31112e-33 0.02825" rpy="0 -0 0" />
            <inertia ixx="0.000184016" ixy="0" ixz="0" iyy="0.000184016" iyz="0" izz="0.000159318" />
        </inertial>
        <visual>
            <origin xyz="0 -1.74512e-18 0" rpy="0 -0 0" />
            <geometry>
                <mesh filename="package://simple_assembly/meshes/Part 1.stl" scale="1 1 1" />
            </geometry>
            <material name="0.800000_0.776471_0.713725_0.000000_0.000000">
                <texture />
                <color rgba="0.8 0.776471 0.713726 1" />
            </material>
        </visual>
    </link>
    <link name="part_1_13">
        <inertial>
            <mass value="0.284011" />
            <origin xyz="-0.0234111 -2.25131e-10 0.0361492" rpy="0 -0 0" />
            <inertia ixx="0.000368023" ixy="4.4845e-12" ixz="8.61899e-05" iyy="0.000382149" iyz="-7.95148e-12" izz="0.000153368" />
        </inertial>
        <visual>
            <origin xyz="0 0 -0.0002" rpy="0 -0 0" />
            <geometry>
                <mesh filename="package://simple_assembly/meshes/Part 1_3.stl" scale="1 1 1" />
            </geometry>
            <material name="0.615686_0.811765_0.929412_0.000000_0.000000">
                <texture />
                <color rgba="0.615686 0.811765 0.929412 1" />
            </material>
        </visual>
    </link>
    <link name="part_1_14">
        <inertial>
            <mass value="0.392289" />
            <origin xyz="-1.88325e-18 2.31112e-33 0.02825" rpy="0 -0 0" />
            <inertia ixx="0.000184016" ixy="0" ixz="0" iyy="0.000184016" iyz="0" izz="0.000159318" />
        </inertial>
        <visual>
            <origin xyz="0 -1.74512e-18 0" rpy="0 -0 0" />
            <geometry>
                <mesh filename="package://simple_assembly/meshes/Part 1.stl" scale="1 1 1" />
            </geometry>
            <material name="0.800000_0.776471_0.713725_0.000000_0.000000">
                <texture />
                <color rgba="0.8 0.776471 0.713726 1" />
            </material>
        </visual>
    </link>
    <link name="part_1_2">
        <inertial>
            <mass value="1.49866" />
            <origin xyz="-9.38573e-18 -8.98462e-20 0.028166" rpy="0 -0 0" />
            <inertia ixx="0.0015335" ixy="0" ixz="0" iyy="0.0015335" iyz="0" izz="0.00224985" />
        </inertial>
        <visual>
            <origin xyz="-1.10049e-17 -3.42901e-18 0" rpy="0 -0 0" />
            <geometry>
                <mesh filename="package://simple_assembly/meshes/Part 1_2.stl" scale="1 1 1" />
            </geometry>
            <material name="0.901961_0.878431_0.811765_0.000000_0.000000">
                <texture />
                <color rgba="0.901961 0.878431 0.811765 1" />
            </material>
        </visual>
    </link>
    <link name="part_1_3">
        <inertial>
            <mass value="1.49866" />
            <origin xyz="1.61912e-18 -8.98462e-20 0.028166" rpy="0 -0 0" />
            <inertia ixx="0.0015335" ixy="0" ixz="0" iyy="0.0015335" iyz="0" izz="0.00224985" />
        </inertial>
        <visual>
            <origin xyz="0 -3.42901e-18 0" rpy="0 -0 0" />
            <geometry>
                <mesh filename="package://simple_assembly/meshes/Part 1_2.stl" scale="1 1 1" />
            </geometry>
            <material name="0.901961_0.878431_0.811765_0.000000_0.000000">
                <texture />
                <color rgba="0.901961 0.878431 0.811765 1" />
            </material>
        </visual>
    </link>
    <link name="part_1_4">
        <inertial>
            <mass value="0.284011" />
            <origin xyz="-0.0234111 -2.25131e-10 0.0361492" rpy="0 -0 0" />
            <inertia ixx="0.000368023" ixy="4.4845e-12" ixz="8.61899e-05" iyy="0.000382149" iyz="-7.95148e-12" izz="0.000153368" />
        </inertial>
        <visual>
            <origin xyz="0 0 -0.0002" rpy="0 -0 0" />
            <geometry>
                <mesh filename="package://simple_assembly/meshes/Part 1_3.stl" scale="1 1 1" />
            </geometry>
            <material name="0.615686_0.811765_0.929412_0.000000_0.000000">
                <texture />
                <color rgba="0.615686 0.811765 0.929412 1" />
            </material>
        </visual>
    </link>
    <link name="part_1_5">
        <inertial>
            <mass value="0.319085" />
            <origin xyz="-3.6505e-08 -1.40559e-08 0.0234998" rpy="0 -0 0" />
            <inertia ixx="0.000124216" ixy="-2.09268e-14" ixz="-2.75013e-13" iyy="0.000124216" iyz="1.7298e-13" izz="0.000131075" />
        </inertial>
        <visual>
            <origin xyz="-3.67805e-08 -1.40564e-08 0" rpy="0 -0 0" />
            <geometry>
                <mesh filename="package://simple_assembly/meshes/Part 1_4.stl" scale="1 1 1" />
            </geometry>
            <material name="0.262745_0.282353_0.301961_0.000000_0.000000">
                <texture />
                <color rgba="0.262745 0.282353 0.301961 1" />
            </material>
        </visual>
    </link>
    <link name="part_1_6">
        <inertial>
            <mass value="0.347331" />
            <origin xyz="0.020796 1.20964e-08 -0.0428943" rpy="0 -0 0" />
            <inertia ixx="0.000768882" ixy="-1.68717e-10" ixz="0.000128098" iyy="0.00060734" iyz="8.33311e-11" izz="0.000443472" />
        </inertial>
        <visual>
            <origin xyz="1.47451e-17 5.86445e-18 -0.06225" rpy="0 -0 0" />
            <geometry>
                <mesh filename="package://simple_assembly/meshes/Part 1_1.stl" scale="1 1 1" />
            </geometry>
            <material name="0.094118_0.580392_0.545098_0.000000_0.000000">
                <texture />
                <color rgba="0.0941176 0.580392 0.545098 1" />
            </material>
        </visual>
    </link>
    <link name="part_1_7">
        <inertial>
            <mass value="1.49866" />
            <origin xyz="1.61912e-18 -8.98462e-20 0.028166" rpy="0 -0 0" />
            <inertia ixx="0.0015335" ixy="0" ixz="0" iyy="0.0015335" iyz="0" izz="0.00224985" />
        </inertial>
        <visual>
            <origin xyz="0 -3.42901e-18 0" rpy="0 -0 0" />
            <geometry>
                <mesh filename="package://simple_assembly/meshes/Part 1_2.stl" scale="1 1 1" />
            </geometry>
            <material name="0.901961_0.878431_0.811765_0.000000_0.000000">
                <texture />
                <color rgba="0.901961 0.878431 0.811765 1" />
            </material>
        </visual>
    </link>
    <link name="part_1_8">
        <inertial>
            <mass value="0.392289" />
            <origin xyz="-1.88325e-18 2.31112e-33 0.02825" rpy="0 -0 0" />
            <inertia ixx="0.000184016" ixy="0" ixz="0" iyy="0.000184016" iyz="0" izz="0.000159318" />
        </inertial>
        <visual>
            <origin xyz="0 -1.74512e-18 0" rpy="0 -0 0" />
            <geometry>
                <mesh filename="package://simple_assembly/meshes/Part 1.stl" scale="1 1 1" />
            </geometry>
            <material name="0.800000_0.776471_0.713725_0.000000_0.000000">
                <texture />
                <color rgba="0.8 0.776471 0.713726 1" />
            </material>
        </visual>
    </link>
    <link name="part_1_9">
        <inertial>
            <mass value="0.319085" />
            <origin xyz="-3.6505e-08 -1.40559e-08 0.0234998" rpy="0 -0 0" />
            <inertia ixx="0.000124216" ixy="-2.09268e-14" ixz="-2.75013e-13" iyy="0.000124216" iyz="1.7298e-13" izz="0.000131075" />
        </inertial>
        <visual>
            <origin xyz="-3.67805e-08 -1.40564e-08 0" rpy="0 -0 0" />
            <geometry>
                <mesh filename="package://simple_assembly/meshes/Part 1_4.stl" scale="1 1 1" />
            </geometry>
            <material name="0.262745_0.282353_0.301961_0.000000_0.000000">
                <texture />
                <color rgba="0.262745 0.282353 0.301961 1" />
            </material>
        </visual>
    </link>
    <link name="root" />
    <joint name="fastened_1_0" type="fixed">
        <origin xyz="0 -1.72433e-18 0" rpy="0 -0 0" />
        <axis xyz="0 0 -1" />
        <parent link="root" />
        <child link="part_1_12" />
    </joint>
    <joint name="fastened_2_0" type="fixed">
        <origin xyz="2.77556e-17 0 0.062" rpy="0 1.5708 1.5708" />
        <axis xyz="-1 0 0" />
        <parent link="part_1_7" />
        <child link="part_1_6" />
    </joint>
    <joint name="fastened_3_0" type="fixed">
        <origin xyz="0.0351604 -1.10739e-08 -0.07495" rpy="-3.14159 6.65171e-15 3.14159" />
        <axis xyz="0 0 -1" />
        <parent link="part_1_6" />
        <child link="part_1_14" />
    </joint>
    <joint name="fastened_4_0" type="fixed">
        <origin xyz="1.62635e-12 -2.81135e-08 0.047" rpy="3.46945e-17 -4.16334e-17 -7.22224e-34" />
        <axis xyz="0 0 -1" />
        <parent link="part_1_9" />
        <child link="part_1_11" />
    </joint>
    <joint name="fastened_5_0" type="fixed">
        <origin xyz="-5.55112e-17 1.38778e-17 0.062" rpy="0 1.5708 -4.71239" />
        <axis xyz="-1 0 0" />
        <parent link="part_1_2" />
        <child link="part_1_1" />
    </joint>
    <joint name="fastened_6_0" type="fixed">
        <origin xyz="0.0351604 -1.10739e-08 -0.07495" rpy="3.14159 1.66533e-16 3.14159" />
        <axis xyz="0 0 -1" />
        <parent link="part_1_1" />
        <child link="part_1" />
    </joint>
    <joint name="fastened_7_0" type="fixed">
        <origin xyz="1.62631e-12 -2.81135e-08 0.047" rpy="5.55112e-17 1.38778e-17 1.38778e-17" />
        <axis xyz="0 0 -1" />
        <parent link="part_1_5" />
        <child link="part_1_4" />
    </joint>
    <joint name="fastened_8_0" type="fixed">
        <origin xyz="0 3.46945e-18 0.062" rpy="0 1.5708 1.5708" />
        <axis xyz="-1 0 0" />
        <parent link="part_1_3" />
        <child link="part_1_10" />
    </joint>
    <joint name="fastened_9_0" type="fixed">
        <origin xyz="0.0351604 -1.10739e-08 -0.07495" rpy="-3.14159 -6.45317e-16 -1.5708" />
        <axis xyz="0 0 -1" />
        <parent link="part_1_10" />
        <child link="part_1_8" />
    </joint>
    <joint name="revolute_1_0" type="revolute">
        <origin xyz="-6.06648e-19 1.57091e-18 0.0565" rpy="4.02289e-19 1.55139e-18 0.448374" />
        <axis xyz="0 0 -1" />
        <parent link="part_1_12" />
        <child link="part_1_13" />
        <limit lower="-3.14159" upper="3.14159" effort="27" velocity="5.45" />
        <dynamics damping="0.1" friction="0.1" />
    </joint>
    <joint name="revolute_2_0" type="revolute">
        <origin xyz="-0.027299 -5.21803e-08 0.0815462" rpy="-1.5708 1.39645 -1.5708" />
        <axis xyz="0 0 1" />
        <parent link="part_1_13" />
        <child link="part_1_7" />
        <limit lower="-1.9199" upper="1.9199" effort="150" velocity="15.71" />
        <dynamics damping="0.1" friction="0.1" />
    </joint>
    <joint name="revolute_3_0" type="revolute">
        <origin xyz="7.24518e-16 -1.38778e-16 0.0565" rpy="-7.29406e-15 7.89324e-15 2.3199" />
        <axis xyz="0 0 -1" />
        <parent link="part_1_14" />
        <child link="part_1_9" />
        <limit lower="-3.14159" upper="3.14159" effort="27" velocity="5.45" />
        <dynamics damping="0.1" friction="0.1" />
    </joint>
    <joint name="revolute_4_0" type="revolute">
        <origin xyz="-0.027299 -5.21803e-08 0.0815462" rpy="1.5708 1.27871 1.5708" />
        <axis xyz="0 0 1" />
        <parent link="part_1_11" />
        <child link="part_1_2" />
        <limit lower="-1.9199" upper="1.9199" effort="150" velocity="15.71" />
        <dynamics damping="0.1" friction="0.1" />
    </joint>
    <joint name="revolute_5_0" type="revolute">
        <origin xyz="3.19189e-16 -3.33067e-16 0.0565" rpy="-5.17019e-16 -2.17006e-15 -1.33298" />
        <axis xyz="0 0 -1" />
        <parent link="part_1" />
        <child link="part_1_5" />
        <limit lower="-3.14159" upper="3.14159" effort="27" velocity="5.45" />
        <dynamics damping="0.1" friction="0.1" />
    </joint>
    <joint name="revolute_6_0" type="revolute">
        <origin xyz="-0.027299 -5.21803e-08 0.0815462" rpy="-1.5708 0.973526 -1.5708" />
        <axis xyz="0 0 1" />
        <parent link="part_1_4" />
        <child link="part_1_3" />
        <limit lower="-1.9199" upper="1.9199" effort="150" velocity="15.71" />
        <dynamics damping="0.1" friction="0.1" />
    </joint>
</robot>
