<!--URDF generated by ONSHAPE BY PTC INC, 1.214-->
<robot name="simple_assembly">
    <link name="cam_mount_assy__1_" />
    <link name="part_1">
        <inertial>
            <mass value="0.392289" />
            <origin xyz="-7.19431e-18 2.31112e-33 0.02825" rpy="0 -0 0" />
            <inertia ixx="0.000184016" ixy="0" ixz="0" iyy="0.000184016" iyz="0" izz="0.000159318" />
        </inertial>
        <visual>
            <origin xyz="-5.31105e-18 -1.74512e-18 0" rpy="0 -0 0" />
            <geometry>
                <mesh filename="package://full_assembly/meshes/Part_1.stl" scale="1 1 1" />
            </geometry>
            <material name="0.800000_0.776471_0.713725_0.000000_0.000000">
                <color rgba="0.8 0.776471 0.713726 1" />
            </material>
        </visual>
    </link>
    <link name="part_1_1">
        <inertial>
            <mass value="0.326785" />
            <origin xyz="0.0216933 3.23641e-08 -0.0482815" rpy="0 -0 0" />
            <inertia ixx="0.000594265" ixy="-2.33687e-11" ixz="0.000101405" iyy="0.000441844" iyz="-4.36749e-10" izz="0.000424915" />
        </inertial>
        <visual>
            <origin xyz="-1.41337e-14 5.86445e-18 -0.06225" rpy="0 -0 0" />
            <geometry>
                <mesh filename="package://full_assembly/meshes/Part_1_1.stl" scale="1 1 1" />
            </geometry>
            <material name="0.917647_0.917647_0.917647_0.000000_0.000000">
                <color rgba="0.917647 0.917647 0.917647 1" />
            </material>
        </visual>
    </link>
    <link name="part_1_10">
        <inertial>
            <mass value="0.326785" />
            <origin xyz="0.0216933 3.23641e-08 -0.0482815" rpy="0 -0 0" />
            <inertia ixx="0.000594265" ixy="-2.33687e-11" ixz="0.000101405" iyy="0.000441844" iyz="-4.36749e-10" izz="0.000424915" />
        </inertial>
        <visual>
            <origin xyz="-1.41337e-14 5.86445e-18 -0.06225" rpy="0 -0 0" />
            <geometry>
                <mesh filename="package://full_assembly/meshes/Part_1_1.stl" scale="1 1 1" />
            </geometry>
            <material name="0.917647_0.917647_0.917647_0.000000_0.000000">
                <color rgba="0.917647 0.917647 0.917647 1" />
            </material>
        </visual>
    </link>
    <link name="part_1_11">
        <inertial>
            <mass value="0.284011" />
            <origin xyz="-0.0234111 -2.25131e-10 0.0361492" rpy="0 -0 0" />
            <inertia ixx="0.000368023" ixy="4.4845e-12" ixz="8.61899e-05" iyy="0.000382149" iyz="-7.95148e-12" izz="0.000153368" />
        </inertial>
        <visual>
            <origin xyz="0 0 -0.0002" rpy="0 -0 0" />
            <geometry>
                <mesh filename="package://full_assembly/meshes/Part_1_3.stl" scale="1 1 1" />
            </geometry>
            <material name="0.917647_0.917647_0.917647_0.000000_0.000000">
                <color rgba="0.917647 0.917647 0.917647 1" />
            </material>
        </visual>
    </link>
    <link name="part_1_12">
        <inertial>
            <mass value="0.392289" />
            <origin xyz="-1.88325e-18 2.31112e-33 0.02825" rpy="0 -0 0" />
            <inertia ixx="0.000184016" ixy="0" ixz="0" iyy="0.000184016" iyz="0" izz="0.000159318" />
        </inertial>
        <visual>
            <origin xyz="0 -1.74512e-18 0" rpy="0 -0 0" />
            <geometry>
                <mesh filename="package://full_assembly/meshes/Part_1.stl" scale="1 1 1" />
            </geometry>
            <material name="0.800000_0.776471_0.713725_0.000000_0.000000">
                <color rgba="0.8 0.776471 0.713726 1" />
            </material>
        </visual>
    </link>
    <link name="part_1_13">
        <inertial>
            <mass value="0.284011" />
            <origin xyz="-0.0234111 -2.25131e-10 0.0361492" rpy="0 -0 0" />
            <inertia ixx="0.000368023" ixy="4.4845e-12" ixz="8.61899e-05" iyy="0.000382149" iyz="-7.95148e-12" izz="0.000153368" />
        </inertial>
        <visual>
            <origin xyz="0 0 -0.0002" rpy="0 -0 0" />
            <geometry>
                <mesh filename="package://full_assembly/meshes/Part_1_3.stl" scale="1 1 1" />
            </geometry>
            <material name="0.917647_0.917647_0.917647_0.000000_0.000000">
                <color rgba="0.917647 0.917647 0.917647 1" />
            </material>
        </visual>
    </link>
    <link name="part_1_14">
        <inertial>
            <mass value="0.392289" />
            <origin xyz="-1.88325e-18 2.31112e-33 0.02825" rpy="0 -0 0" />
            <inertia ixx="0.000184016" ixy="0" ixz="0" iyy="0.000184016" iyz="0" izz="0.000159318" />
        </inertial>
        <visual>
            <origin xyz="0 -1.74512e-18 0" rpy="0 -0 0" />
            <geometry>
                <mesh filename="package://full_assembly/meshes/Part_1.stl" scale="1 1 1" />
            </geometry>
            <material name="0.800000_0.776471_0.713725_0.000000_0.000000">
                <color rgba="0.8 0.776471 0.713726 1" />
            </material>
        </visual>
    </link>
    <link name="part_1_15">
        <inertial>
            <mass value="9.94808e-05" />
            <origin xyz="-4.05706e-08 1.55401e-08 -0.015" rpy="0 -0 0" />
            <inertia ixx="3.37032e-08" ixy="0" ixz="0" iyy="3.37032e-08" iyz="0" izz="5.25037e-08" />
        </inertial>
        <visual>
            <origin xyz="-4.09465e-08 1.55389e-08 -0.03" rpy="0 -0 0" />
            <geometry>
                <mesh filename="package://full_assembly/meshes/Part_1_5.stl" scale="1 1 1" />
            </geometry>
            <material name="0.615686_0.811765_0.929412_0.000000_0.000000">
                <color rgba="0.615686 0.811765 0.929412 1" />
            </material>
        </visual>
    </link>
    <link name="part_1_16">
        <inertial>
            <mass value="7.29541e-05" />
            <origin xyz="-2.19833e-05 -2.09428e-08 0.00997844" rpy="0 -0 0" />
            <inertia ixx="2.62877e-08" ixy="-1.14213e-15" ixz="2.83597e-12" iyy="2.63584e-08" iyz="3.65213e-15" izz="4.77548e-08" />
        </inertial>
        <visual>
            <origin xyz="-4.76287e-08 -1.8008e-08 0.01125" rpy="0 -0 0" />
            <geometry>
                <mesh filename="package://full_assembly/meshes/Part_1_6.stl" scale="1 1 1" />
            </geometry>
            <material name="0.615686_0.811765_0.929412_0.000000_0.000000">
                <color rgba="0.615686 0.811765 0.929412 1" />
            </material>
        </visual>
    </link>
    <link name="part_1_17">
        <inertial>
            <mass value="3.51671e-05" />
            <origin xyz="-0.0013579 0.0396975 -0.00952187" rpy="0 -0 0" />
            <inertia ixx="1.25577e-08" ixy="6.63795e-10" ixz="-3.27558e-10" iyy="2.86745e-08" iyz="8.6627e-10" izz="3.81891e-08" />
        </inertial>
        <visual>
            <origin xyz="0 -2.14926e-18 -0.0185" rpy="0 -0 0" />
            <geometry>
                <mesh filename="package://full_assembly/meshes/Part_1_7.stl" scale="1 1 1" />
            </geometry>
            <material name="0.615686_0.811765_0.929412_0.000000_0.000000">
                <color rgba="0.615686 0.811765 0.929412 1" />
            </material>
        </visual>
    </link>
    <link name="part_1_2">
        <inertial>
            <mass value="1.49866" />
            <origin xyz="-9.38573e-18 -8.98462e-20 0.028166" rpy="0 -0 0" />
            <inertia ixx="0.0015335" ixy="0" ixz="0" iyy="0.0015335" iyz="0" izz="0.00224985" />
        </inertial>
        <visual>
            <origin xyz="-1.10049e-17 -3.42901e-18 0" rpy="0 -0 0" />
            <geometry>
                <mesh filename="package://full_assembly/meshes/Part_1_2.stl" scale="1 1 1" />
            </geometry>
            <material name="0.901961_0.878431_0.811765_0.000000_0.000000">
                <color rgba="0.901961 0.878431 0.811765 1" />
            </material>
        </visual>
    </link>
    <link name="part_1_3">
        <inertial>
            <mass value="1.49866" />
            <origin xyz="1.61912e-18 -8.98462e-20 0.028166" rpy="0 -0 0" />
            <inertia ixx="0.0015335" ixy="0" ixz="0" iyy="0.0015335" iyz="0" izz="0.00224985" />
        </inertial>
        <visual>
            <origin xyz="0 -3.42901e-18 0" rpy="0 -0 0" />
            <geometry>
                <mesh filename="package://full_assembly/meshes/Part_1_2.stl" scale="1 1 1" />
            </geometry>
            <material name="0.901961_0.878431_0.811765_0.000000_0.000000">
                <color rgba="0.901961 0.878431 0.811765 1" />
            </material>
        </visual>
    </link>
    <link name="part_1_4">
        <inertial>
            <mass value="0.284011" />
            <origin xyz="-0.0234111 -2.25131e-10 0.0361492" rpy="0 -0 0" />
            <inertia ixx="0.000368023" ixy="4.4845e-12" ixz="8.61899e-05" iyy="0.000382149" iyz="-7.95148e-12" izz="0.000153368" />
        </inertial>
        <visual>
            <origin xyz="0 0 -0.0002" rpy="0 -0 0" />
            <geometry>
                <mesh filename="package://full_assembly/meshes/Part_1_3.stl" scale="1 1 1" />
            </geometry>
            <material name="0.917647_0.917647_0.917647_0.000000_0.000000">
                <color rgba="0.917647 0.917647 0.917647 1" />
            </material>
        </visual>
    </link>
    <link name="part_1_5">
        <inertial>
            <mass value="0.319085" />
            <origin xyz="-3.6505e-08 -1.40559e-08 0.0234998" rpy="0 -0 0" />
            <inertia ixx="0.000124216" ixy="-2.09268e-14" ixz="-2.75013e-13" iyy="0.000124216" iyz="1.7298e-13" izz="0.000131075" />
        </inertial>
        <visual>
            <origin xyz="-3.67805e-08 -1.40564e-08 0" rpy="0 -0 0" />
            <geometry>
                <mesh filename="package://full_assembly/meshes/Part_1_4.stl" scale="1 1 1" />
            </geometry>
            <material name="0.262745_0.282353_0.301961_0.000000_0.000000">
                <color rgba="0.262745 0.282353 0.301961 1" />
            </material>
        </visual>
    </link>
    <link name="part_1_6">
        <inertial>
            <mass value="0.326785" />
            <origin xyz="0.0216933 3.23641e-08 -0.0482815" rpy="0 -0 0" />
            <inertia ixx="0.000594265" ixy="-2.33687e-11" ixz="0.000101405" iyy="0.000441844" iyz="-4.36749e-10" izz="0.000424915" />
        </inertial>
        <visual>
            <origin xyz="-1.41337e-14 5.86445e-18 -0.06225" rpy="0 -0 0" />
            <geometry>
                <mesh filename="package://full_assembly/meshes/Part_1_1.stl" scale="1 1 1" />
            </geometry>
            <material name="0.917647_0.917647_0.917647_0.000000_0.000000">
                <color rgba="0.917647 0.917647 0.917647 1" />
            </material>
        </visual>
    </link>
    <link name="part_1_7">
        <inertial>
            <mass value="1.49866" />
            <origin xyz="1.61912e-18 -8.98462e-20 0.028166" rpy="0 -0 0" />
            <inertia ixx="0.0015335" ixy="0" ixz="0" iyy="0.0015335" iyz="0" izz="0.00224985" />
        </inertial>
        <visual>
            <origin xyz="0 -3.42901e-18 0" rpy="0 -0 0" />
            <geometry>
                <mesh filename="package://full_assembly/meshes/Part_1_2.stl" scale="1 1 1" />
            </geometry>
            <material name="0.901961_0.878431_0.811765_0.000000_0.000000">
                <color rgba="0.901961 0.878431 0.811765 1" />
            </material>
        </visual>
    </link>
    <link name="part_1_8">
        <inertial>
            <mass value="0.392289" />
            <origin xyz="-1.88325e-18 2.31112e-33 0.02825" rpy="0 -0 0" />
            <inertia ixx="0.000184016" ixy="0" ixz="0" iyy="0.000184016" iyz="0" izz="0.000159318" />
        </inertial>
        <visual>
            <origin xyz="0 -1.74512e-18 0" rpy="0 -0 0" />
            <geometry>
                <mesh filename="package://full_assembly/meshes/Part_1.stl" scale="1 1 1" />
            </geometry>
            <material name="0.800000_0.776471_0.713725_0.000000_0.000000">
                <color rgba="0.8 0.776471 0.713726 1" />
            </material>
        </visual>
    </link>
    <link name="part_1_9">
        <inertial>
            <mass value="0.319085" />
            <origin xyz="-3.6505e-08 -1.40559e-08 0.0234998" rpy="0 -0 0" />
            <inertia ixx="0.000124216" ixy="-2.09268e-14" ixz="-2.75013e-13" iyy="0.000124216" iyz="1.7298e-13" izz="0.000131075" />
        </inertial>
        <visual>
            <origin xyz="-3.67805e-08 -1.40564e-08 0" rpy="0 -0 0" />
            <geometry>
                <mesh filename="package://full_assembly/meshes/Part_1_4.stl" scale="1 1 1" />
            </geometry>
            <material name="0.262745_0.282353_0.301961_0.000000_0.000000">
                <color rgba="0.262745 0.282353 0.301961 1" />
            </material>
        </visual>
    </link>
    <link name="root" />
    <joint name="fastened_1_0" type="fixed">
        <origin xyz="0 -1.72433e-18 0" rpy="0 -0 0" />
        <axis xyz="0 0 -1" />
        <parent link="root" />
        <child link="part_1_12" />
    </joint>
    <joint name="fastened_1_1" type="fixed">
        <origin xyz="-4.76287e-08 -1.8008e-08 0.013" rpy="-2.77556e-17 -3.46945e-18 4.81482e-35" />
        <axis xyz="0 0 1" />
        <parent link="part_1_16" />
        <child link="cam_mount_assy__1_" />
    </joint>
    <joint name="fastened_2_0" type="fixed">
        <origin xyz="-2.77556e-17 0 0.062" rpy="0 1.5708 1.5708" />
        <axis xyz="-1 0 0" />
        <parent link="part_1_7" />
        <child link="part_1_6" />
    </joint>
    <joint name="fastened_2_1" type="fixed">
        <origin xyz="-3.18511e-08 -3.86443e-08 0.0195" rpy="-1.76942e-16 2.42861e-17 -1.5708" />
        <axis xyz="0 0 1" />
        <parent link="part_1_16" />
        <child link="part_1_17" />
    </joint>
    <joint name="fastened_3_0" type="fixed">
        <origin xyz="-3.18511e-08 -3.86443e-08 0.0195" rpy="3.14159 1.20737e-15 1.17961e-15" />
        <axis xyz="0 0 -1" />
        <parent link="part_1_16" />
        <child link="part_1_15" />
    </joint>
    <joint name="fastened_3_1" type="fixed">
        <origin xyz="0.0351604 -1.10739e-08 -0.07495" rpy="-3.14159 6.6664e-15 3.14159" />
        <axis xyz="0 0 -1" />
        <parent link="part_1_6" />
        <child link="part_1_14" />
    </joint>
    <joint name="fastened_4_0" type="fixed">
        <origin xyz="1.62635e-12 -2.81135e-08 0.047" rpy="-3.46945e-17 1.38778e-17 -2.40741e-34" />
        <axis xyz="0 0 -1" />
        <parent link="part_1_9" />
        <child link="part_1_11" />
    </joint>
    <joint name="fastened_5_0" type="fixed">
        <origin xyz="0 3.1225e-17 0.062" rpy="0 1.5708 -4.71239" />
        <axis xyz="-1 0 0" />
        <parent link="part_1_2" />
        <child link="part_1_1" />
    </joint>
    <joint name="fastened_6_0" type="fixed">
        <origin xyz="0.0351604 -1.10739e-08 -0.07495" rpy="3.14159 1.11022e-16 3.14159" />
        <axis xyz="0 0 -1" />
        <parent link="part_1_1" />
        <child link="part_1" />
    </joint>
    <joint name="fastened_7_0" type="fixed">
        <origin xyz="1.62642e-12 -2.81135e-08 0.047" rpy="2.77556e-17 6.93889e-18 -1.38778e-17" />
        <axis xyz="0 0 -1" />
        <parent link="part_1_5" />
        <child link="part_1_4" />
    </joint>
    <joint name="fastened_8_0" type="fixed">
        <origin xyz="0 4.85723e-17 0.062" rpy="0 1.5708 1.5708" />
        <axis xyz="-1 0 0" />
        <parent link="part_1_3" />
        <child link="part_1_10" />
    </joint>
    <joint name="fastened_9_0" type="fixed">
        <origin xyz="0.0351604 -1.10739e-08 -0.07495" rpy="-3.14159 -8.39606e-16 -1.5708" />
        <axis xyz="0 0 -1" />
        <parent link="part_1_10" />
        <child link="part_1_8" />
    </joint>
    <joint name="revolute_1_0" type="revolute">
        <origin xyz="1.17451e-25 1.72433e-18 0.0565" rpy="0 0 0" />
        <axis xyz="0 0 -1" />
        <parent link="part_1_12" />
        <child link="part_1_13" />
        <limit lower="-6.28318" upper="6.28318" effort="150.0" velocity="15.71" />
    </joint>
    <joint name="revolute_2_0" type="revolute">
        <origin xyz="-0.027299 -5.21803e-08 0.0815462" rpy="-1.5708 0 -1.5708" />
        <axis xyz="0 0 1" />
        <parent link="part_1_13" />
        <child link="part_1_7" />
        <limit lower="-1.5708" upper="1.5708" effort="27.0" velocity="5.45" />
    </joint>
    <joint name="revolute_3_0" type="revolute">
        <origin xyz="-2.92192e-17 0 0.0565" rpy="0 0 0" />
        <axis xyz="0 0 -1" />
        <parent link="part_1_14" />
        <child link="part_1_9" />
        <limit lower="-6.28318" upper="6.28318" effort="150.0" velocity="15.71" />
    </joint>
    <joint name="revolute_4_0" type="revolute">
        <origin xyz="-0.027299 -5.21803e-08 0.0815462" rpy="1.5708 3.14159 1.5708" />
        <axis xyz="0 0 1" />
        <parent link="part_1_11" />
        <child link="part_1_2" />
        <limit lower="-1.91986" upper="1.91986" effort="27.0" velocity="5.45" />
    </joint>
    <joint name="revolute_5_0" type="revolute">
        <origin xyz="2.498e-16 1.11022e-16 0.0565" rpy="0 0 0" />
        <axis xyz="0 0 -1" />
        <parent link="part_1" />
        <child link="part_1_5" />
        <limit lower="-6.28318" upper="6.28318" effort="150.0" velocity="15.71" />
    </joint>
    <joint name="revolute_6_0" type="revolute">
        <origin xyz="-0.027299 -5.21803e-08 0.0815462" rpy="-1.5708 0 -1.5708" />
        <axis xyz="0 0 1" />
        <parent link="part_1_4" />
        <child link="part_1_3" />
        <limit lower="-1.91986" upper="1.91986" effort="27.0" velocity="5.45" />
    </joint>
    <joint name="revolute_7_0" type="revolute">
        <origin xyz="5.55112e-17 0 0.0565" rpy="0 0 1.5708" />
        <axis xyz="0 0 -1" />
        <parent link="part_1_8" />
        <child link="part_1_16" />
        <limit lower="-3.14159" upper="3.14159" effort="150.0" velocity="15.71" />
    </joint>

    <link name="wrist_link" />
    <joint name="wrist_link_joint" type="fixed">
        <origin xyz="0 0 0" rpy="0 0 0" />
        <parent link="part_1_16" />
        <child link="wrist_link" />
    </joint>
</robot>
