<!--URDF generated by ONSHAPE BY PTC INC, 1.213-->
<robot name="simple_turret">
    <link name="part_1">
        <inertial>
            <mass value="1.49866" />
            <origin xyz="1.61912e-18 -8.98462e-20 0.028166" rpy="0 -0 0" />
            <inertia ixx="0.0015335" ixy="0" ixz="0" iyy="0.0015335" iyz="0" izz="0.00224985" />
        </inertial>
        <visual>
            <origin xyz="0 -3.42901e-18 0" rpy="0 -0 0" />
            <geometry>
                <mesh filename="package://simple_turret/meshes/Part 1.stl" scale="1 1 1" />
            </geometry>
            <material name="0.901961_0.878431_0.811765_0.000000_0.000000">
                <texture />
                <color rgba="0.901961 0.878431 0.811765 1" />
            </material>
        </visual>
    </link>
    <link name="part_1_1">
        <inertial>
            <mass value="0.392289" />
            <origin xyz="-1.88325e-18 2.31112e-33 -0.02825" rpy="0 -0 0" />
            <inertia ixx="0.000184016" ixy="0" ixz="0" iyy="0.000184016" iyz="0" izz="0.000159318" />
        </inertial>
        <visual>
            <origin xyz="0 -1.74512e-18 -0.0565" rpy="0 -0 0" />
            <geometry>
                <mesh filename="package://simple_turret/meshes/Part 1_1.stl" scale="1 1 1" />
            </geometry>
            <material name="0.800000_0.776471_0.713725_0.000000_0.000000">
                <texture />
                <color rgba="0.8 0.776471 0.713726 1" />
            </material>
        </visual>
    </link>
    <link name="part_1_2">
        <inertial>
            <mass value="0.000105555" />
            <origin xyz="-0.0242053 -2.11781e-10 0.0325355" rpy="0 -0 0" />
            <inertia ixx="1.30623e-07" ixy="2.01732e-15" ixz="2.82613e-08" iyy="1.28931e-07" iyz="-3.40211e-15" izz="6.53473e-08" />
        </inertial>
        <visual>
            <origin xyz="0 1.75124e-18 -0.004" rpy="0 -0 0" />
            <geometry>
                <mesh filename="package://simple_turret/meshes/Part 1_2.stl" scale="1 1 1" />
            </geometry>
            <material name="0.615686_0.811765_0.929412_0.000000_0.000000">
                <texture />
                <color rgba="0.615686 0.811765 0.929412 1" />
            </material>
        </visual>
    </link>
    <link name="root" />
    <joint name="fastened_1_0" type="fixed">
        <origin xyz="0 0 0" rpy="3.14159 -0 0" />
        <axis xyz="0 0 1" />
        <parent link="root" />
        <child link="part_1_1" />
    </joint>
    <joint name="pan" type="revolute">
        <origin xyz="0 1.75124e-18 -0.0565" rpy="3.14159 -0 0" />
        <axis xyz="0 0 -1" />
        <parent link="part_1_1" />
        <child link="part_1_2" />
        <limit lower="-3.14159" upper="3.14159" effort="10" velocity="3.14159"/>
    </joint>
    <joint name="tilt" type="revolute">
        <origin xyz="-0.0273 -1.0921e-07 0.0729055" rpy="1.5708 -1.48511 1.5708" />
        <axis xyz="0 0 -1" />
        <parent link="part_1_2" />
        <child link="part_1" />
        <limit lower="-3.14159" upper="3.14159" effort="10" velocity="3.14159"/>
    </joint>
</robot>
